Workbook
Name ´2: 'CATEGORIAS MEDICINAS'!$B$8
Name ACARIGUA: adm!$F$2:$F$5
Name ADMIN1: [1]!Table486[NAMESTADO]
Name ADMIN1: [2]!Table48[NAMESTADO]
Name Admin1_Linked_Pcode: [3]!Admin2_1['#adm1+code]
Name ADMIN11: [2]!Table48[NAMESTADO]
Name ADMIN1NAME: [1]!Table374[NAMEESTADO]
Name ADMIN1NAME: [2]!Table37[NAMEESTADO]
Name ADMIN2: [1]!Table109[ConcateEstaMuni]
Name ADMIN2: [2]!Table10[ConcateEstaMuni]
Name Admin2_Linked_Pcode: [3]!Admin3_1['#adm2+code]
Name ADMIN2CODE: [1]!Table486[[#Headers],[PCODEMUNI]]
Name ADMIN2CODE: [2]!Table48[[#Headers],[PCODEMUNI]]
Name Admin3: [3]!Admin3_1['#adm3+name]
Name ADMIN3CODE: [1]!Table109[[#Headers],[PCODEPARROQUIA]]
Name ADMIN3CODE: [2]!Table10[[#Headers],[PCODEPARROQUIA]]
Name AEE_kit_type_T: [3]!AEE_kit_type['#kit+type]
Name Agua_Higiene_Saneamiento_WASH: 'Validación Actividades'!$C$2:$C$9
Name Alianzas: 'Validación Actividades'!$T$2
Name AMAZONAS: adm!$B$4:$B$10
Name Analgésicos_Antipiréticos_AINES: 'CATEGORIAS MEDICINAS'!$C$8:$C$25
Name Anestésicos: 'CATEGORIAS MEDICINAS'!$C$1:$C$7
Name Antialérgicos: 'CATEGORIAS MEDICINAS'!$C$26:$C$31
Name Antiamebianos_Antileishmaniasis: 'CATEGORIAS MEDICINAS'!$C$84:$C$90
Name Antiasmáticos_Antitusígenos: 'CATEGORIAS MEDICINAS'!$C$248:$C$253
Name Antibióticos_Antifúngicos_Antivirales: 'CATEGORIAS MEDICINAS'!$H$32:$H$66
Name Antidiabéticos: 'CATEGORIAS MEDICINAS'!$C$174:$C$182
Name Antidiarreico_sales_de_rehidratación_oral: 'CATEGORIAS MEDICINAS'!$H$146:$H$149
Name Antiepilécticos: 'CATEGORIAS MEDICINAS'!$C$32:$C$38
Name Antiespasmódicos: 'CATEGORIAS MEDICINAS'!$C$207:$C$213
Name Antihelmínticos_Antiparasitarios: 'CATEGORIAS MEDICINAS'!$C$39:$C$46
Name Antiinflamatorios: 'CATEGORIAS MEDICINAS'!$C$163:$C$170
Name Antimaláricos: 'CATEGORIAS MEDICINAS'!$C$91:$C$101
Name Antituberculosis: 'CATEGORIAS MEDICINAS'!$C$112:$C$118
Name ANZOATEGUI: adm!$B$12:$B$32
Name APURE: adm!$B$34:$B$40
Name ARAGUA: adm!$B$42:$B$58
Name BARCELONA: adm!$G$2:$G$15
Name BARINAS: adm!$H$2:$H$15
Name BARINAS_: adm!$B$61:$B$72
Name BARQUISIMETO: adm!$I$2:$I$11
Name BOLIVAR: adm!$B$74:$B$84
Name CABIMAS: adm!$J$2:$J$10
Name CALABOZO: adm!$K$2:$K$8
Name Cambio_Comportamiento_Bienestar_Social_CCBS: 'Validación Actividades'!$D$2:$D$6
Name Capacitaciones: 'Validación Actividades'!$V$4
Name CARABOBO: adm!$B$86:$B$99
Name CARACAS: adm!$L$2:$L$10
Name CARONI: adm!$AM$2
Name CARUPANO: adm!$M$2:$M$8
Name CIUDAD_BOLIVAR: adm!$N$2:$N$10
Name COJEDES: adm!$B$101:$B$109
Name Comedores: 'Validación Actividades'!#REF!
Name CORO: adm!$O$2:$O$8
Name CUMANA: adm!$P$2:$P$6
Name Database: #REF!
Name Database: #REF!
Name Database: #REF!
Name Database: #REF!
Name Database: #REF!

Sheet Indicaciones
C2: Actualización Julio 2020
B3: ¿Qué es un Reporte Mensual DIOCESANO?
B5: Cáritas tiene como objetivo monitorear la presencia operacional en las actividades de respuesta de las Diocesis
B7: Recuerden que el reporte es una herramienta para poner en común información de las Diocesis para poder hacer análisis de brechas de cobertura. Nuestro enfoque es de poder identificar rápidamente nuestras acciones a nivel nacional
B9: Debe reportarse los 3 últimos dias de cada mes y enviar a basededatoscaritasvenezuela@gmail.com en el titulo del correo y el nombre del archivo deben indicar el nombre de la Diocesis y mes del Reporte
B11: ¿Como llenar el Reporte Mensual de Cáritas?
B13: 1. Solo llenar las columnas en blanco, las columnas en color azul estan bloquedas.
B14: Para la comodidad del transcriptor hay columnas que se llenan solas o estan solo en formato de numeros estas nos sirven para contabilizar la información mas rápidamente, es decir, no se podran colocar numeros y letras en la misma casilla Ej. 5años, no se podra hacer la información que se solicita es solo el numero.
B16: 2. Por favor tengan cuidado con el copiar-pegar
B17: Por ejemplo si hacen un clic y arrastran sin averiguar, los números pueden cambiar para hacer una cadena de números al revés de replicarse. (ej. 101, 102, 103, etc.) con esta accion podrian elimar las formulas que estan predeterminadas, para la accion de cortar y pegar deberan seleccionar mas de una fila para que le den a opcion de arrastrar.
B19: ACTUALIZACIONES
B21: . Pestaña Resumen: es una manera rapida y visual de ver la accion del mes de cada Diocesis.
B23: a. Para la Pestaña de SALUD
... B48: SAMAN DE NIÑOS Y NIÑAS
B49: N° | C49: Numero correlativo, este numero tiene relacion con la historia que tiene el niño en la Parroquia o Diocesis
B50: TIPO DE INGRESO | C50: Lista de Validación
B51: N° Control | C51: Numero ( 0 / 10000) numero de semana que tiene el niño en el control
B52: DIOCESIS | C52: Lista de Validación
B53: ESTADO | C53: se auto-llena Lista de Validación Anidadas (depende del listado de la Diocesis)
B54: MUNICIPIO | C54: Lista de Validación Anidadas (depende del listado de Estado)
B55: PARROQUIA CIVIL / COMUNIDAD | C55: Precisar la Parroquia Civil o comunidad
B56: PARROQUIA ECLESIAL | C56: Lista de Validación Anidadas (depende del listado de Centinelas proporcionado por las Diocesis)
B57: MES | C57: Lista de Validación
B58: AÑO | C58: Lista de Validación
B59: CENTRO | C59: se auto-llena
B60: GRUPO ETNICO | C60: Colocar el nombre del grupo etnico
... B102: REFERIDO S/N | C102: Lista de Validación
B103: Observaciones
B105: EMBARAZADAS Y LACTANTES
B106: #
B107: FECHA DE MEDICIÓN | C107: DD/MM/AAAA
B108: TIPO DE INGRESO | C108: DIAGNOSTICO INICIAL
B109: NOMBRE
B110: APELLIDO
B111: FECHA NACIMIENTO | C111: DD/MM/AAAA
B112: EMBARAZADA ó LACTANTE | C112: EMBARAZADA
B113: SEMANA DE GESTACIÓN | C113: Numero ( 0 / 10000)
B114: EDAD | C114: se auto-llena
B115: EDEMA | C115: SI
B116: BRAZO (CM) | C116: Numero ( 0 / 100)
...

Sheet adm
A1: ESTADO | B1: MUNICIPIO | C1: NOMBRE DE LA DIOCESIS | D1: ESTADO | E1: CODIGO DE IDENTIFICACION DE LA DIOCESIS | F1: ACARIGUA | G1: BARCELONA | H1: BARINAS | I1: BARQUISIMETO | J1: CABIMAS | K1: CALABOZO | L1: CARACAS | M1: CARUPANO | N1: CIUDAD BOLIVAR | O1: CORO | P1: CUMANA | Q1: GUASDUALITO | R1: LA GUAIRA | S1: LOS TEQUES | T1: MACHIQUES | U1: MARACAIBO | V1: MARACAY | W1: MATURIN | X1: MERIDA | Y1: PUERTO CABELLO | Z1: PUNTO FIJO | AA1: SAN FELIPE | AB1: SAN FERNANDO | AC1: TRUJILLO | AD1: VALENCIA | AE1: PUERTO_AYACUCHO | AF1: GUARENAS | AG1: EL_VIGIA | AH1: SAN_CRISTOBAL | AI1: SAN_CARLOS | AJ1: MARGARITA | AK1: EL_TIGRE | AL1: TUCUPITA | AM1: CARONI | AN1: VALLE_DE_LA_PASCUA
A2: Caracas | B2: 1. Municipio Libertador (Caracas) | C2: ACARIGUA | D2: PORTUGUESA | E2: D18AC | F2: CORAZON DE JESUS | G2: VIRGEN DE FATIMA | H2: SAN ISIDRO LABRADOR | I2: NTRA SRA DE GUADALUPE | J2: OTRO- COLOCAR EL NOMBRE EN LA PARROQUIA CIVIL | K2: NTRA SRA DE FATIMA | L2: SANTO CRISTO | M2: DIVINA MISERICORDIA | N2: SAN PABLO APOSTOL | O2: NTRA SRA DE FATIMA | P2: CRISTO RESUCITADO | Q2: NTRA SRA DEL CARMEN | R2: ESPIRITU SANTO | S2: CURIA DIOSESANA CARITAS LOS TEQUES | T2: BUEN PASTOR | U2: JESUS BUEN PASTOR | V2: SAGRADA FAMILIA | W2: SANTO DOMINGO DE GUZMAN | X2: PARROQUIA SANTO DOMINGO DE GUZMÁN. MUNICIPIO CARDENAL QUINTERO | Y2: CATEDRAL SAN JOSE | Z2: SAGRADO CORAZON DE JESUS | AA2: ESPIRITU SANTO | AB2: NTRA SRA DEL ROSARIO | AC2: MARIA AUXILIADORA | AD2: CORPUS CHRISTI | AE2: OTRO- COLOCAR EL NOMBRE EN LA PARROQUIA CIVIL | AF2: OTRO- COLOCAR EL NOMBRE EN LA PARROQUIA CIVIL | AG2: OTRO- COLOCAR EL NOMBRE EN LA PARROQUIA CIVIL | AH2: OTRO- COLOCAR EL NOMBRE EN LA PARROQUIA CIVIL | AI2: OTRO- COLOCAR EL NOMBRE EN LA PARROQUIA CIVIL | AJ2: OTRO- COLOCAR EL NOMBRE EN LA PARROQUIA CIVIL | AK2: OTRO- COLOCAR EL NOMBRE EN LA PARROQUIA CIVIL | AL2: OTRO- COLOCAR EL NOMBRE EN LA PARROQUIA CIVIL | AM2: OTRO- COLOCAR EL NOMBRE EN LA PARROQUIA CIVIL | AN2: OTRO- COLOCAR EL NOMBRE EN LA PARROQUIA CIVIL
C3: BARCELONA | D3: ANZOATEGUI | E3: D06BR | F3: SANTA BARBARA | G3: SANTISIMO SACRAMENTO | H3: DIVINO NIÑO | I3: NSTRA SRA GUADALUPE BOBARE | K3: VIRGEN DEL VALLE | L3: SAN JOSE OBRERO | M3: SAN JUAN BAUTISTA | N3: NTRA SRA DEL VALLE | O3: SAN JOSE OBRERO | P3: NTRA SRA DE FATIMA | Q3: SAN MIGUEL ARCANGEL | R3: INMACULADO CORAZON DE MARIA | S3: NTRA SRA DE LA ASUNCION | T3: CRISTO REY | U3: JESUS REDENTOR | V3: OTRO- COLOCAR EL NOMBRE EN LA PARROQUIA CIVIL | W3: SAN IGNACIO DE LOYOLA | X3: PARROQUIA SAN RAFAEL ARCÁNGEL. MUNICIPIO RANGEL | Y3: CRISTO REY | Z3: NTRA SRA DE GUADALUPE | AA3: ESPIRITU SANTO YARITAGUA | AB3: MARIA AUXILIADORA | AC3: NTRA SRA DEL CARMEN | AD3: NTRA SRA DE GUADALUPE
A4: Amazonas | B4: 1. Municipio Alto Orinoco (La Esmeralda). | C4: BARINAS | D4: BARINAS_ | E4: D03BN | F4: SANTA ELENA | G4: NTRA SRA DE COROMOTO | H4: CARITAS BARINAS | I4: SAN JUAN BOSCO | K4: SANTA ROSA DE LIMA | L4: SAN MONS ROMERO | M4: SAN MARTIN DE PORRES | N4: SANTA EDUVIGIS | O4: SANTA ANA DE CORO | P4: NTRA SRA DEL ROSARIO | Q4: SANTISIMA TRINIDAD | R4: MARIA AUXILIADORA | S4: SAGRADO CORAZON DE JESUS Y MARIA | T4: EL ROSARIO | U4: SAN JUAN BAUTISTA | W4: CRISTO RESUCITADO | X4: PARROQUIA SANTA LUCÍA: MUNICIPIO RANGEL | Y4: SAN JOSE OBRERO | Z4: SAN JOSE DE TACUATO | AA4: NTRA SRA DE LAS MERCEDES | AB4: SANTA LUCIA | AC4: SAN PEDRO | AD4: MARIA MADRE DE LA IGLESIA
B5: 2. Municipio Atabapo (San Fernando de Atabapo). | C5: BARQUISIMETO | D5: LARA | E5: D13BQ | F5: SAN FRANCISCO JAVIER | G5: CATEDRAL BARCELONA | H5: CRISTO REY | I5: SAN JUAN PABLO II | K5: NTRA SRA DE GUADALUPE | L5: LA ENCARNACIÓN DEL VALLE | M5: SAN RAFAEL ARCANGEL | N5: INMACULADA | O5: OTRO- COLOCAR EL NOMBRE EN LA PARROQUIA CIVIL | P5: NTRA SRA DE LA ESPERANZA | Q5: SAN CAMILO LELIS | R5: NTRA SEÐORA DEL CARMEN | S5: SAN DIEGO DE ALCALA ALTOS MIRANDINOS | T5: INMACULADA | U5: SANTISIMO SALVADOR | W5: SAN CARLOS BORROMEO | X5: PARROQUIA INMACULADA CONCEPCIÓN. MUNICIPIO RANGEL | Y5: SAN PIO X | Z5: OTRO- COLOCAR EL NOMBRE EN LA PARROQUIA CIVIL | AA5: NTRA SRA DEL ROSARIO DE FATIMA | AB5: SAN JOSE DEL YAGUAL | AC5: SAGRADO CORAZON DE JESUS | AD5: MARIA MADRE DEL REDENTOR
B6: 3. Municipio Atures (Puerto Ayacucho). | C6: CABIMAS | D6: ZULIA | E6: D23CB | F6: OTRO- COLOCAR EL NOMBRE EN LA PARROQUIA CIVIL | G6: CORAZON DE JESUS | H6: NTRA SRA DE LA ESPERANZA | I6: SAN NICOLAS DE BARI | K6: SAN JOSE OBRERO | L6: CASA DE LA MISERICORDIA | M6: SAN JUAN BAUTISTA YAGUARAPARO | N6: ESPIRITU SANTO | O6: SAN FRANCISCO DE ASIS | P6: OTRO- COLOCAR EL NOMBRE EN LA PARROQUIA CIVIL | Q6: OTRO- COLOCAR EL NOMBRE EN LA PARROQUIA CIVIL | R6: SAGRADO CORAZON DE JESUS | S6: SAN FRANCISCO DE PAULA | T6: SAGRADA FAMILIA | U6: NTRA SRA COROMOTO Y SAN JOSE OBRERO | W6: VIRGEN DEL VALLE | X6: PARROQUIA NTRA. SRA. DE LA MILAGROSA. MUNICIPIO LIBERTADOR | Y6: NTRA SRA DE GUADALUPE | AA6: SANTA EDUVIGIS | AB6: SANTUARIO JESUS DE NAZARENO | AC6: SAN MIGUEL | AD6: NTRA SRA DE BEGOÑA
B7: 4. Municipio Autana (Isla Ratón). | C7: CALABOZO | D7: GUARICO | E7: D12CZ | G7: NTRA SRA DE LOURDES | H7: NTRA SRA DEL ROSARIO | I7: NTRA SRA DE LAS MERCEDES | K7: SAN JUAN PABLO II | L7: SAN JOAQUIN Y SANTA ANA | M7: NTRA SRA DE COROMOTO | N7: SAN ANTONIO DE PADUA | O7: SANTO NIÑO DE JESUS | R7: SAN FRANCISCO DE ASIS | S7: SANTA LUCIA VIRGEN Y MARTIN | T7: SAN EUGENIO | U7: SAN BENITO DE PALERMO | W7: OTRO- COLOCAR EL NOMBRE EN LA PARROQUIA CIVIL | X7: PARROQUIA INMACULADO CORAZÓN DE MARÍA. MUNICIPIO LIBERTADOR | Y7: OTRO- COLOCAR EL NOMBRE EN LA PARROQUIA CIVIL | AA7: NTRA SRA DEL CARMEN | AB7: SAGRADA FAMILIA DE NAZARET | AC7: SAN AGUSTIN HIPONA | AD7: SAN JOSE DE CALASANZ
B8: 5. Municipio Manapiare (San Juan de Manapiare). | C8: CARACAS | D8: DTO_CAPITAL | E8: D01CCS | G8: NUESTRA SEÑORA DEL CARMEN | H8: SAGRADA FAMILIA | I8: SANTA CRUZ | K8: OTRO- COLOCAR EL NOMBRE EN LA PARROQUIA CIVIL | L8: SANTO DOMINGO SAVIO | M8: OTRO- COLOCAR EL NOMBRE EN LA PARROQUIA CIVIL | N8: SAN JOSE | O8: OTRO- COLOCAR EL NOMBRE EN LA PARROQUIA CIVIL | R8: SAN MARTIN DE PORRES | S8: NTRA SRA DE COROMOTO | T8: SAN JOSE | U8: SANTISIMO SACRAMENTO | X8: PARROQUIA NTRA. SRA. DEL ROSARIO. MUNICIPIO LIBERTADOR | AA8: EL NAZARENO | AB8: NTRA SRA DEL VALLE | AC8: OTRO- COLOCAR EL NOMBRE EN LA PARROQUIA CIVIL | AD8: SAN JUAN MARIA VIANNEY
B9: 6. Municipio Maroa (Maroa). | C9: CARONI | D9: BOLIVAR | E9: D07CR | G9: NTRA SRA DEL ROSARIO DE POMPEI | H9: SANTO DOMINGO DE GUZMAN | I9: SAN ANTONIO DE PADUA | L9: NTRA SRA DE LA ENCARNACION DEL VALLE | N9: JESÚS DE NAZARET | R9: SAN MIGUEL ARCANGEL | S9: NTRA SRA DEL ROSARIO | T9: CATERAL MACHIQUES | U9: SAN RAFAEL ARCANGEL | X9: PARROQUIA SAN JOSÉ OBRERO. MUNICIPIO LIBERTADOR | AA9: VICARIA SAN ISIDRO | AB9: LA MILAGROSA | AD9: LA MILAGROSA
B10: 7. Municipio Río Negro (San Carlos de Río Negro). | C10: CARUPANO | D10: SUCRE | E10: D19CP | G10: SAN CELESTINO MARTIR | H10: MEDALLA MILAGROSA | I10: NTRA SRA DEL CARMEN | L10: OTRO- COLOCAR EL NOMBRE EN LA PARROQUIA CIVIL | N10: OTRO- COLOCAR EL NOMBRE EN LA PARROQUIA CIVIL | R10: SANTISIMA TRINIDAD | S10: STA ROSA DE LIMA | T10: MISION DEL TUKUKO | U10: SAN RAMON NONATO | X10: PARROQUIA BASÍLICA SANTA LUCIA. MUNICIPIO MIRANDA | AA10: SAN GERONIMO | AB10: INMACULADA CONCEPCION | AD10: SAGRADO CORAZON DE JESUS DE AGUIRRE
C11: CIUDAD_BOLIVAR | D11: BOLIVAR | E11: D07BV | G11: DIVINA PASTORA | H11: SAN PEDRO APOSTOL | I11: OTRO- COLOCAR EL NOMBRE EN LA PARROQUIA CIVIL | R11: STO CRISTO DE LA MISERICORDIA | S11: CASA HNAS AGUSTINA | T11: SAN IGNACIO | U11: SAN MIGUEL ARCANGEL | X11: SANTUARIO SAN BUENAVENTURA. MUNICIPIO CAMPO ELÍAS | AA11: SANTA LUCIA | AB11: NTRA SRA DE GUADALUPE | AD11: SAN JUAN BAUTISTA
A12: Anzoátegui | B12: 1. Municipio Anaco (Anaco). | C12: CIUDAD GUAYANA | D12: BOLIVAR | E12: D11CR | G12: SANTA LUCIA MARTIR | H12: SAN JOSE/LA CARAMUCA | R12: NTRA SRA GUARACARUMBO | S12: SAN DIEGO ALCALA OCUMARE | T12: NTRA SRA DE CHIQUINQUIRA | U12: INMACULADA CONCEPCION DE CARRASQUERO | X12: SANTUARIO INMACULADA CONCEPCIÓN. MUNICIPIO ANDRÉS BELLO | AA12: NTRA SRA DE LA VICTORIA | AB12: OTRO- COLOCAR EL NOMBRE EN LA PARROQUIA CIVIL | AD12: NTRA SRA DEL CARMEN
B13: 2. Municipio Aragua (Aragua de Barcelona). | C13: CORO | D13: FALCON | E13: D19CN | G13: ROSA MISTICA | H13: SANTISIMA TRINIDAD | R13: SAN SEBASTIAN | S13: SAN JOSE OBRERO | T13: SAN PEDRO APOSTOL | U13: NTRA SRA DE LOURDES ISLA DE TOAS | X13: PARROQUIA NTRA. SRA. DEL CARMEN. MUNICIPIO CAMPO ELÍAS | AA13: PURISIMA CONCEPCION DE TINAJAS | AD13: SANTA EDUVIGIS
B14: 3. Municipio Bolívar (Barcelona). | C14: CUMANA | D14: SUCRE | E14: D03TG | G14: SANTA CRUZ | H14: SANTA ROSA DE LIMA/CALDERAS | R14: SAN JOSE CARAYACA | S14: SAGRADO CORAZON DE JESUS | T14: SANTISIMA TRINIDAD | U14: SAN MARTIN DE PORRES | X14: PARROQUIA SAN ANTONIO DE PADUA. MUNICIPIO LIBERTADOR | AA14: OTRO- COLOCAR EL NOMBRE EN LA PARROQUIA CIVIL | AD14: INMACULADA CONCEPCION
B15: 4. Municipio Bruzual (Clarines). | C15: EL_TIGRE | D15: ANZOATEGUI | E15: D23EV | G15: OTRO- COLOCAR EL NOMBRE EN LA PARROQUIA CIVIL | H15: SAN MARTIN DE PORRES/CAMIRI | R15: NTRA SRA DEL VALLE | S15: NTRA SRA DE LA MACARENA | T15: NTRA SRA DEL CARMEN | U15: OTRO- COLOCAR EL NOMBRE EN LA PARROQUIA CIVIL | X15: PARROQUIA NTRA. SRA. DE LA CANDELARIA. MUNICIPIO ANTONIO PINTO SALINA | AD15: OTRO- COLOCAR EL NOMBRE EN LA PARROQUIA CIVIL
B16: 5. Municipio Cajigal (Onoto). | C16: EL_VIGIA | D16: ZULIA/MÉRIDA | E16: D15GN | H16: OTRO- COLOCAR EL NOMBRE EN LA PARROQUIA CIVIL | R16: SAN JOSE OBRERO | S16: SAN PEDRO APOSTOL | T16: OTRO- COLOCAR EL NOMBRE EN LA PARROQUIA CIVIL | X16: PARROQUIA NTRA. SRA. DE FÁTIMA. MUNICIPIO TOVAR
B17: 6. Municipio Carvajal (Valle de Guanape). | C17: GUANARE | D17: MIRANDA | E17: D04GD | R17: BEATA MARIA JOSE | S17: NTRA SRA DE FATIMA | X17: PARROQUIA NTRA. SRA. DEL CARMEN. MUNICIPIO ARZOBISPO CHACÓN
B18: 7. Municipio Diego Bautista Urbaneja (Lechería). | C18: GUARENAS | D18: APURE | E18: D24LG | R18: OTRO- COLOCAR EL NOMBRE EN LA PARROQUIA CIVIL | S18: SAN MARTIN DE PORRES NUEVA CUA | X18: PARROQUIA NTRA. SRA. DE COROMOTO. MUNICIPIO LIBERTADOR
B19: 8. Municipio Freites (Cantaura). | C19: GUASDUALITO | D19: VARGAS | E19: D15TQ | S19: OTRO- COLOCAR EL NOMBRE EN LA PARROQUIA CIVIL | X19: PARROQUIA SAN ANTONIO DE PADUA. MUNICIPIO SUCRE
B20: 9. Municipio Guanipa (San José de Guanipa). | C20: LA_GUAIRA | D20: MIRANDA | E20: D23MQ | X20: PARROQUIA SAN FRANCISCO DE ASÍS. MUNICIPIO LIBERTADOR
B21: 10. Municipio Guanta (Guanta). | C21: LOS_TEQUES | D21: ZULIA | E21: D23MB | X21: OTRO- COLOCAR EL NOMBRE EN LA PARROQUIA CIVIL
B22: 11. Municipio Independencia (Soledad). | C22: MACHIQUES | D22: ZULIA | E22: D05MC
B23: 12. Municipio Libertad (San Mateo). | C23: MARACAIBO I | D23: ZULIA | E23: DMG
B24: 13. Municipio McGregor (El Chaparro). | C24: MARACAIBO II | D24: ARAGUA | E24: D16MR
B25: 14. Municipio Miranda (Pariaguán) | C25: MARACAY | D25: ESPARTA | E25: D25MR
B26: 15. Municipio Monagas (San Diego de Cabrutica) | C26: MARGARITA | D26: MONAGAS | E26: DPA
B27: 16. Municipio Peñalver (Puerto Píritu) | C27: MATURIN | D27: MERIDA_ | E27: D08PTC
B28: 17. Municipio Píritu (Píritu). | C28: MERIDA | D28: BOLIVAR | E28: D11PF
B29: 18. Municipio San Juan de Capistrano (Boca de Uchire). | C29: PUERTO_AYACUCHO | D29: CARABOBO | E29: DSC
B30: 19. Municipio Santa Ana (Santa Ana). | C30: PUERTO_CABELLO | D30: FALCON | E30: DSCC
B31: 20. Municipio Simón Rodriguez (El Tigre). | C31: PUNTO_FIJO | D31: TACHIRA | E31: D22SF
B32: 21. Municipio Sotillo (Puerto La Cruz). | C32: SAN_CRISTOBAL | D32: COJEDES | E32: D04SFA
C33: SAN_CARLOS | D33: YARACUY | E33: D21TJ
A34: Apure | B34: 1. Municipio Achaguas (Achaguas). | C34: SAN_FELIPE | D34: APURE | E34: DTUP
B35: 2. Municipio Biruaca (Biruaca). | C35: SAN_FERNANDO | D35: TRUJILLO_ | E35: D08VL
B36: 3. Municipio Muñoz (Bruzual). | C36: TRUJILLO | D36: DELTA AMACURO | E36: D12CVP
B37: 4. Municipio Páez (Guasdualito). | C37: TUCUPITA | D37: CARABOBO
B38: 5. Municipio Pedro Camejo (San Juan de Payara). | C38: VALENCIA | D38: GUARICO
B39: 6. Municipio Rómulo Gallegos (Elorza). | C39: VALLE_DE_LA_PASCUA
B40: 7. Municipio San Fernando (San Fernando de Apure).
...

Sheet CATEGORIAS MEDICINAS
A1: 1 | B1: Anestésicos | C1: 1. Ketamina Ampollas | F1: 1 | G1: Anestésicos | H1: 1. Ketamina Ampollas | I1: Anestésicos | J1: 1
C2: 1. Lidocaína Ampollas | F2: 1 | G2: Anestésicos | H2: 1. Lidocaína Ampollas | I2: Anestésicos | J2: 1
C3: 1. Naloxona Ampollas | F3: 1 | G3: Anestésicos | H3: 1. Naloxona Ampollas | I3: Anestésicos | J3: 1
C4: 1. Otro…Anestésicos | F4: 1 | G4: Anestésicos | H4: 1. Otro…Anestésicos | I4: Anestésicos | J4: 1
F5: 2 | G5: Analgésicos_Antipiréticos_AINES | H5: 2. Ácido acetilsalicílico | I5: Analgésicos_Antipiréticos_AINES | J5: 2
F6: 2 | G6: Analgésicos_Antipiréticos_AINES | H6: 2. Diclofenac Gel | I6: Analgésicos_Antipiréticos_AINES | J6: 2
F7: 2 | G7: Analgésicos_Antipiréticos_AINES | H7: 2. Diclofenac Potasico | I7: Analgésicos_Antipiréticos_AINES | J7: 2
A8: 2 | B8: Analgésicos_Antipiréticos_AINES | C8: 2. Ácido acetilsalicílico | F8: 2 | G8: Analgésicos_Antipiréticos_AINES | H8: 2. Diclofenac Sódico | I8: Analgésicos_Antipiréticos_AINES | J8: 2
C9: 2. Diclofenac Gel | F9: 2 | G9: Analgésicos_Antipiréticos_AINES | H9: 2. Diclofenac Sódico Ampollas | I9: Analgésicos_Antipiréticos_AINES | J9: 2
C10: 2. Diclofenac Potasico | F10: 2 | G10: Analgésicos_Antipiréticos_AINES | H10: 2. Ibuprofeno 400 mg | I10: Analgésicos_Antipiréticos_AINES | J10: 2
C11: 2. Diclofenac Sódico | F11: 2 | G11: Analgésicos_Antipiréticos_AINES | H11: 2. Ibuprofeno tabs | I11: Analgésicos_Antipiréticos_AINES | J11: 2
C12: 2. Diclofenac Sódico Ampollas | F12: 2 | G12: Analgésicos_Antipiréticos_AINES | H12: 2. Ibuprofeno, Suspensión oral | I12: Analgésicos_Antipiréticos_AINES | J12: 2
C13: 2. Ibuprofeno 400 mg | F13: 2 | G13: Analgésicos_Antipiréticos_AINES | H13: 2. Paracetamol 100mg | I13: Analgésicos_Antipiréticos_AINES | J13: 2
C14: 2. Ibuprofeno tabs | F14: 2 | G14: Analgésicos_Antipiréticos_AINES | H14: 2. Paracetamol 500mg | I14: Analgésicos_Antipiréticos_AINES | J14: 2
C15: 2. Ibuprofeno, Suspensión oral | F15: 2 | G15: Analgésicos_Antipiréticos_AINES | H15: 2. Paracetamol Ampollas | I15: Analgésicos_Antipiréticos_AINES | J15: 2
C16: 2. Paracetamol 100mg | F16: 2 | G16: Analgésicos_Antipiréticos_AINES | H16: 2. Paracetamol supositorios | I16: Analgésicos_Antipiréticos_AINES | J16: 2
C17: 2. Paracetamol 500mg | F17: 2 | G17: Analgésicos_Antipiréticos_AINES | H17: 2. Paracetamol, Suspensión oral | I17: Analgésicos_Antipiréticos_AINES | J17: 2
C18: 2. Paracetamol Ampollas | F18: 2 | G18: Analgésicos_Antipiréticos_AINES | H18: 2. Tramadol tabs./caps | I18: Analgésicos_Antipiréticos_AINES | J18: 2
C19: 2. Paracetamol supositorios | F19: 2 | G19: Analgésicos_Antipiréticos_AINES | H19: 2. Otro… Analgésicos_Antipiréticos_AINES | I19: Analgésicos_Antipiréticos_AINES | J19: 2
C20: 2. Paracetamol, Suspensión oral | F20: 3 | G20: Antialérgicos | H20: 3. Prometazina | I20: Antialérgicos | J20: 3
... C22: 2. Otro… Analgésicos_Antipiréticos_AINES | F22: 3 | G22: Antialérgicos | H22: 3. Otro... Antialérgicos | I22: Antialérgicos | J22: 3
F23: 4 | G23: Antiepilépticos_Anticonvulsivantes | H23: 4. Carbamazepina | I23: Antiepilécticos | J23: 4
F24: 4 | G24: Antiepilépticos_Anticonvulsivantes | H24: 4. Fenitoína Sódica | I24: Antiepilécticos | J24: 4
F25: 4 | G25: Antiepilépticos_Anticonvulsivantes | H25: 4. Levodopa + Carbidopa | I25: Antiepilécticos | J25: 4
A26: 3 | B26: Antialérgicos | C26: 3. Prometazina | F26: 4 | G26: Antiepilépticos_Anticonvulsivantes | H26: 4. Otro…Antiepilépticos/anticonvulsivo | I26: Antiepilécticos | J26: 4
C27: 3. Prometazina Ampollas | F27: 5 | G27: Antihelmínticos_Antiparasitarios | H27: 5. Albendazol tabs. 400 mg | I27: Antihelmínticos_Antiparasitarios | J27: 5
C28: 3. Otro... Antialérgicos | F28: 5 | G28: Antihelmínticos_Antiparasitarios | H28: 5. Albendazol tabs. masticables 200 mg | I28: Antihelmínticos_Antiparasitarios | J28: 5
F29: 5 | G29: Antihelmínticos_Antiparasitarios | H29: 5. Mebendazol 500 mg | I29: Antihelmínticos_Antiparasitarios | J29: 5
F30: 5 | G30: Antihelmínticos_Antiparasitarios | H30: 5. Mebendazol tabs. 100 mg | I30: Antihelmínticos_Antiparasitarios | J30: 5
F31: 5 | G31: Antihelmínticos_Antiparasitarios | H31: 5. Otro…Antihelmínticos_Antiparasitarios | I31: Antihelmínticos_Antiparasitarios | J31: 5
A32: 4 | B32: Antiepilécticos | C32: 4. Carbamazepina | F32: 6 | G32: Antibióticos_Antifúngicos_Antivirales | H32: 6. Amoxicilina 250 mg + Ácido Clavulánico 62,5 mg/5 ml para suspensión oral | I32: Antibióticos_Antifúngicos_Antivirales | J32: 6
C33: 4. Fenitoína Sódica | F33: 6 | G33: Antibióticos_Antifúngicos_Antivirales | H33: 6. Amoxicilina 875 mg+ acido clavulanico | I33: Antibióticos_Antifúngicos_Antivirales | J33: 6
C34: 4. Levodopa + Carbidopa | F34: 6 | G34: Antibióticos_Antifúngicos_Antivirales | H34: 6. Amoxicilina dispersable 10x10 250mg | I34: Antibióticos_Antifúngicos_Antivirales | J34: 6
C35: 4. Otro…Antiepilécticos | F35: 6 | G35: Antibióticos_Antifúngicos_Antivirales | H35: 6. Amoxicilina para Suspensión oral 125 mg/5 ml | I35: Antibióticos_Antifúngicos_Antivirales | J35: 6
F36: 6 | G36: Antibióticos_Antifúngicos_Antivirales | H36: 6. Amoxicilina tabs./caps. 250 mg | I36: Antibióticos_Antifúngicos_Antivirales | J36: 6
F37: 6 | G37: Antibióticos_Antifúngicos_Antivirales | H37: 6. Amoxicilina tabs./caps. 500 mg | I37: Antibióticos_Antifúngicos_Antivirales | J37: 6
F38: 6 | G38: Antibióticos_Antifúngicos_Antivirales | H38: 6. Ampicilina Sódica para inyectar 1g | I38: Antibióticos_Antifúngicos_Antivirales | J38: 6
A39: 5 | B39: Antihelmínticos_Antiparasitarios | C39: 5. Albendazol tabs. 400 mg | F39: 6 | G39: Antibióticos_Antifúngicos_Antivirales | H39: 6. Cefalexina caps. 250 mg | I39: Antibióticos_Antifúngicos_Antivirales | J39: 6
C40: 5. Albendazol tabs. masticables 200 mg | F40: 6 | G40: Antibióticos_Antifúngicos_Antivirales | H40: 6. Cefixima tabs. 200 mg | I40: Antibióticos_Antifúngicos_Antivirales | J40: 6
C41: 5. Mebendazol 500 mg | F41: 6 | G41: Antibióticos_Antifúngicos_Antivirales | H41: 6. Ceftriaxona para inyectar 1.000 mg (Substancia seca) | I41: Antibióticos_Antifúngicos_Antivirales | J41: 6
...

Sheet Resumen
C1: Pestaña N° | D1: Resumen de Gestión Diocesana | E1: Beneficiarios directos de la acción | F1: DIOCESIS | G1: MES | H1: AÑO
C2: 1 | D2: N° de Niños con evaluación Talla/Peso (Total de Niños medidos)
C3: 1 | D3: N° de Niños identificados en Alerta (z-score 0)
C4: 1 | D4: N° de Niños identificados en Manejo Preventivo (Riesgo z-score -1 )
C5: 1 | D5: N° de Niños identificados con Desnutricion GAM Moderada (z-score -2 )
C6: 1 | D6: N° de Niños identificados con Desnutricion GAM Severa (z-score -3 )
C7: 1 | D7: N° de Niños Desparasitados de 2 - 5 años
C8: 1 | D8: N° de Niños en vivero con atencion según protocolo
C9: 1 | D9: N° de Niños Recuperados
C10: 2 | D10: N° de Embarazadas/Lactantes evaluadas (Total Medidas C. Brazo)
C11: 2 | D11: N° de Embarazadas/Lactantes Desparasitadas
C12: 2 | D12: N° de Embarazadas/Lactantes con bajo peso (>23cm)
C13: 2 | D13: N° de Kits Embarazadas (Acido Folico + Vitaminas) entregados
... C18: 4 | D18: N° de Consultas Psicologicas
C19: 4.1 | D19: N° de Medicinas entregadas
C20: 6 | D20: N° de Capacitaciones a benediciarios de las comunidades
C21: 6 | D21: N° de Participantes en capacitaciones comunitarias
C22: 6 | D22: N° de Capacitaciones a Voluntarios/Promotores de Caritas
C23: 6 | D23: Participantes en capacitaciones a Cáritas
C24: 7 | D24: N° de Encuestas Hogares realizadas
C25: 8 | D25: N° de Beneficiarios del Fondo solidario
C26: 8 | D26: N° de Beneficiarios Kits de higiene
C27: 8 | D27: N° de Beneficiarios Filtros artesanales
C28: 8 | D28: N° de Beneficiarios Pastillas purificadoras
C29: 9 | D29: N° de Beneficiarios Kits de Proteccion COVID-19
C30: 8 | D30: N° de Beneficiarios Kits de alimentos
C31: 10 | D31: N° de Encuestas Percepcion realizadas
... C33: 14 | D33: N° de Salas Situacional

Sheet 0. LOCALIZACIÓN
B3: ESTADO | C3: MUNICIPIO | D3: PARROQUIA
B4: Distrito Capital | C4: Libertador | D4: Altagracia
B5: Distrito Capital | C5: Libertador | D5: Antimano
B6: Distrito Capital | C6: Libertador | D6: Candelaria
B7: Distrito Capital | C7: Libertador | D7: Caricuao
B8: Distrito Capital | C8: Libertador | D8: Catedral
B9: Distrito Capital | C9: Libertador | D9: Coche
B10: Distrito Capital | C10: Libertador | D10: El Junquito
B11: Distrito Capital | C11: Libertador | D11: El Paraíso
B12: Distrito Capital | C12: Libertador | D12: El Recreo
B13: Distrito Capital | C13: Libertador | D13: El Valle
B14: Distrito Capital | C14: Libertador | D14: La Pastora
... B1138: La Guaira | C1138: Vargas | D1138: Carlos Soublette

Sheet 1. SAMAN NIÑOS
A1: N° | B1: DIOCESIS | C1: ESTADO | D1: MUNICIPIO | E1: PARROQUIA CIVIL | F1: PARROQUIA ECLESIAL / CENTRO CENTINELA | G1: SECTOR O COMUNIDAD | H1: GRUPO ETNICO | I1: CÉDULA DE IDENTIDAD de la madre o cuidador (ingrese solo números sin espacios) | J1: EDAD (de la madre o cuidador) | K1: PARENTESCO con el niño / niña | L1: TIPO DE INGRESO | M1: N° Control / N° de Semana | N1: N° de Historia o Código del niño | O1: Nombres del niño o niña | P1: Apellidos del niño o niña | Q1: Sexo | R1: Fecha de Nacimiento dd/mm/aaaa | S1: Fecha de Medición dd/mm/aaaa | T1: Edad (Años y Meses) | U1: Rango de Edad | V1: ¿Tiene condición de discapacidad? | W1: En caso afirmativo indique: ¿Cúal? | X1: Edema | Y1: Hemoglobina (g/dL) | Z1: C. BRAZO (cm) | AA1: Clasificación PB | AB1: TALLA (cm) | AC1: PESO (kg) | AD1: Z-Score (ZPT) | AE1: Estado Nutricional | AF1: Desparasitado en la jornada | AG1: Tratamiento suministrado Según Protocolo Cáritas | AH1: Cantidad Suministrada (sobres o unidades) | AI1: Otros Complementos | AJ1: FECHA INICIO DE VIVERO | AK1: FECHA SALIDA DE VIVERO | AL1: Z-Score (ZPT) ENTRADA | AM1: Z-Score (ZPT) SALIDA | AN1: SAMANAS DE DURACION EN VIVERO | AO1: SITUACÍON A LA SALIDA | AP1: REFERIDO AL MEDICO | AQ1: Observaciones | AR1: MES | AS1: AÑO | AT1: CENTRO | AU1: CODIGO DE DIOCESIS | AV1: Indicar si el niño es Beneficiario del Proyecto TENGO
A2: 1 | N2: =AU2&R2&A2 -> 1 | T2: =IF(R2="","",(S2-R2)/365) | U2: =IF(R2="","",IF(T2<=0.6,"0-6 meses",IF(T2<=2,"7-23 meses",IF(T2<=5,"24-59 meses",IF(T2>5,"Mayor a 5 años"))))) | AA2: =IF(ISBLANK(Z2),"ERROR",IF(AND(Z2>=12.5,Z2<=35),"Adecuado",IF(AND(Z2<11.5,Z2>=9),"Desnutrición aguda severa",IF(AND(Z2>=11.5,Z2<12.5),"Desnutrición aguda moderada",IF(AND(Z2>=6,Z2<9),"Referencia valoración médica",IF(Z2<6,"Dato inválido",IF(Z2>35,"Dato inválido"))))))) -> ERROR | AE2: =IF(ISBLANK(AD2),"ERROR",IF(AND(AD2>3,AD2<5),"Obesidad",IF(AND(AD2>2,AD2<=3),"Sobrepeso",IF(AND(AD2<=2,AD2>=-2),"Adecuado",IF(AND(AD2>=-3,AD2<-2),"Desnutrición aguda moderada",IF(AND(AD2<-3,AD2>-5),"Desnutrición aguda severa",IF(AD2<=-5,"Dato inválido",IF(AD2>=5,"Dato inválido")))))))) -> ERROR | AR2: =IF(D2="","",TEXT(S2,"MMMM")) | AS2: =IF(F2="","",TEXT(S2,"YYYY")) | AT2: =B2&" - "&E2 -> - | AU2: =IFERROR(VLOOKUP(B2,adm!$C$2:$E$36,3,FALSE),"")
A3: 2 | N3: =AU3&R3&A3 -> 2 | T3: =IF(R3="","",(S3-R3)/365) | U3: =IF(R3="","",IF(T3<=0.6,"0-6 meses",IF(T3<=2,"7-23 meses",IF(T3<=5,"24-59 meses",IF(T3>5,"Mayor a 5 años"))))) | AA3: =IF(ISBLANK(Z3),"ERROR",IF(AND(Z3>=12.5,Z3<=35),"Adecuado",IF(AND(Z3<11.5,Z3>=9),"Desnutrición aguda severa",IF(AND(Z3>=11.5,Z3<12.5),"Desnutrición aguda moderada",IF(AND(Z3>=6,Z3<9),"Referencia valoración médica",IF(Z3<6,"Dato inválido",IF(Z3>35,"Dato inválido"))))))) -> ERROR | AE3: =IF(ISBLANK(AD3),"ERROR",IF(AND(AD3>3,AD3<5),"Obesidad",IF(AND(AD3>2,AD3<=3),"Sobrepeso",IF(AND(AD3<=2,AD3>=-2),"Adecuado",IF(AND(AD3>=-3,AD3<-2),"Desnutrición aguda moderada",IF(AND(AD3<-3,AD3>-5),"Desnutrición aguda severa",IF(AD3<=-5,"Dato inválido",IF(AD3>=5,"Dato inválido")))))))) -> ERROR | AR3: =IF(D3="","",TEXT(S3,"MMMM")) | AS3: =IF(F3="","",TEXT(S3,"YYYY")) | AT3: =B3&" - "&E3 -> - | AU3: =IFERROR(VLOOKUP(B3,adm!$C$2:$E$36,3,FALSE),"")
A4: 3 | N4: =AU4&R4&A4 -> 3 | T4: =IF(R4="","",(S4-R4)/365) | U4: =IF(R4="","",IF(T4<=0.6,"0-6 meses",IF(T4<=2,"7-23 meses",IF(T4<=5,"24-59 meses",IF(T4>5,"Mayor a 5 años"))))) | AA4: =IF(ISBLANK(Z4),"ERROR",IF(AND(Z4>=12.5,Z4<=35),"Adecuado",IF(AND(Z4<11.5,Z4>=9),"Desnutrición aguda severa",IF(AND(Z4>=11.5,Z4<12.5),"Desnutrición aguda moderada",IF(AND(Z4>=6,Z4<9),"Referencia valoración médica",IF(Z4<6,"Dato inválido",IF(Z4>35,"Dato inválido"))))))) -> ERROR | AE4: =IF(ISBLANK(AD4),"ERROR",IF(AND(AD4>3,AD4<5),"Obesidad",IF(AND(AD4>2,AD4<=3),"Sobrepeso",IF(AND(AD4<=2,AD4>=-2),"Adecuado",IF(AND(AD4>=-3,AD4<-2),"Desnutrición aguda moderada",IF(AND(AD4<-3,AD4>-5),"Desnutrición aguda severa",IF(AD4<=-5,"Dato inválido",IF(AD4>=5,"Dato inválido")))))))) -> ERROR | AR4: =IF(D4="","",TEXT(S4,"MMMM")) | AS4: =IF(F4="","",TEXT(S4,"YYYY")) | AT4: =B4&" - "&E4 -> - | AU4: =IFERROR(VLOOKUP(B4,adm!$C$2:$E$36,3,FALSE),"")
A5: 4 | N5: =AU5&R5&A5 -> 4 | T5: =IF(R5="","",(S5-R5)/365) | U5: =IF(R5="","",IF(T5<=0.6,"0-6 meses",IF(T5<=2,"7-23 meses",IF(T5<=5,"24-59 meses",IF(T5>5,"Mayor a 5 años"))))) | AA5: =IF(ISBLANK(Z5),"ERROR",IF(AND(Z5>=12.5,Z5<=35),"Adecuado",IF(AND(Z5<11.5,Z5>=9),"Desnutrición aguda severa",IF(AND(Z5>=11.5,Z5<12.5),"Desnutrición aguda moderada",IF(AND(Z5>=6,Z5<9),"Referencia valoración médica",IF(Z5<6,"Dato inválido",IF(Z5>35,"Dato inválido"))))))) -> ERROR | AE5: =IF(ISBLANK(AD5),"ERROR",IF(AND(AD5>3,AD5<5),"Obesidad",IF(AND(AD5>2,AD5<=3),"Sobrepeso",IF(AND(AD5<=2,AD5>=-2),"Adecuado",IF(AND(AD5>=-3,AD5<-2),"Desnutrición aguda moderada",IF(AND(AD5<-3,AD5>-5),"Desnutrición aguda severa",IF(AD5<=-5,"Dato inválido",IF(AD5>=5,"Dato inválido")))))))) -> ERROR | AR5: =IF(D5="","",TEXT(S5,"MMMM")) | AS5: =IF(F5="","",TEXT(S5,"YYYY")) | AT5: =B5&" - "&E5 -> - | AU5: =IFERROR(VLOOKUP(B5,adm!$C$2:$E$36,3,FALSE),"")
A6: 5 | N6: =AU6&R6&A6 -> 5 | T6: =IF(R6="","",(S6-R6)/365) | U6: =IF(R6="","",IF(T6<=0.6,"0-6 meses",IF(T6<=2,"7-23 meses",IF(T6<=5,"24-59 meses",IF(T6>5,"Mayor a 5 años"))))) | AA6: =IF(ISBLANK(Z6),"ERROR",IF(AND(Z6>=12.5,Z6<=35),"Adecuado",IF(AND(Z6<11.5,Z6>=9),"Desnutrición aguda severa",IF(AND(Z6>=11.5,Z6<12.5),"Desnutrición aguda moderada",IF(AND(Z6>=6,Z6<9),"Referencia valoración médica",IF(Z6<6,"Dato inválido",IF(Z6>35,"Dato inválido"))))))) -> ERROR | AE6: =IF(ISBLANK(AD6),"ERROR",IF(AND(AD6>3,AD6<5),"Obesidad",IF(AND(AD6>2,AD6<=3),"Sobrepeso",IF(AND(AD6<=2,AD6>=-2),"Adecuado",IF(AND(AD6>=-3,AD6<-2),"Desnutrición aguda moderada",IF(AND(AD6<-3,AD6>-5),"Desnutrición aguda severa",IF(AD6<=-5,"Dato inválido",IF(AD6>=5,"Dato inválido")))))))) -> ERROR | AR6: =IF(D6="","",TEXT(S6,"MMMM")) | AS6: =IF(F6="","",TEXT(S6,"YYYY")) | AT6: =B6&" - "&E6 -> - | AU6: =IFERROR(VLOOKUP(B6,adm!$C$2:$E$36,3,FALSE),"")
A7: 6 | N7: =AU7&R7&A7 -> 6 | T7: =IF(R7="","",(S7-R7)/365) | U7: =IF(R7="","",IF(T7<=0.6,"0-6 meses",IF(T7<=2,"7-23 meses",IF(T7<=5,"24-59 meses",IF(T7>5,"Mayor a 5 años"))))) | AA7: =IF(ISBLANK(Z7),"ERROR",IF(AND(Z7>=12.5,Z7<=35),"Adecuado",IF(AND(Z7<11.5,Z7>=9),"Desnutrición aguda severa",IF(AND(Z7>=11.5,Z7<12.5),"Desnutrición aguda moderada",IF(AND(Z7>=6,Z7<9),"Referencia valoración médica",IF(Z7<6,"Dato inválido",IF(Z7>35,"Dato inválido"))))))) -> ERROR | AE7: =IF(ISBLANK(AD7),"ERROR",IF(AND(AD7>3,AD7<5),"Obesidad",IF(AND(AD7>2,AD7<=3),"Sobrepeso",IF(AND(AD7<=2,AD7>=-2),"Adecuado",IF(AND(AD7>=-3,AD7<-2),"Desnutrición aguda moderada",IF(AND(AD7<-3,AD7>-5),"Desnutrición aguda severa",IF(AD7<=-5,"Dato inválido",IF(AD7>=5,"Dato inválido")))))))) -> ERROR | AR7: =IF(D7="","",TEXT(S7,"MMMM")) | AS7: =IF(F7="","",TEXT(S7,"YYYY")) | AT7: =B7&" - "&E7 -> - | AU7: =IFERROR(VLOOKUP(B7,adm!$C$2:$E$36,3,FALSE),"")
A8: 7 | N8: =AU8&R8&A8 -> 7 | T8: =IF(R8="","",(S8-R8)/365) | U8: =IF(R8="","",IF(T8<=0.6,"0-6 meses",IF(T8<=2,"7-23 meses",IF(T8<=5,"24-59 meses",IF(T8>5,"Mayor a 5 años"))))) | AA8: =IF(ISBLANK(Z8),"ERROR",IF(AND(Z8>=12.5,Z8<=35),"Adecuado",IF(AND(Z8<11.5,Z8>=9),"Desnutrición aguda severa",IF(AND(Z8>=11.5,Z8<12.5),"Desnutrición aguda moderada",IF(AND(Z8>=6,Z8<9),"Referencia valoración médica",IF(Z8<6,"Dato inválido",IF(Z8>35,"Dato inválido"))))))) -> ERROR | AE8: =IF(ISBLANK(AD8),"ERROR",IF(AND(AD8>3,AD8<5),"Obesidad",IF(AND(AD8>2,AD8<=3),"Sobrepeso",IF(AND(AD8<=2,AD8>=-2),"Adecuado",IF(AND(AD8>=-3,AD8<-2),"Desnutrición aguda moderada",IF(AND(AD8<-3,AD8>-5),"Desnutrición aguda severa",IF(AD8<=-5,"Dato inválido",IF(AD8>=5,"Dato inválido")))))))) -> ERROR | AR8: =IF(D8="","",TEXT(S8,"MMMM")) | AS8: =IF(F8="","",TEXT(S8,"YYYY")) | AT8: =B8&" - "&E8 -> - | AU8: =IFERROR(VLOOKUP(B8,adm!$C$2:$E$36,3,FALSE),"")
A9: 8 | N9: =AU9&R9&A9 -> 8 | T9: =IF(R9="","",(S9-R9)/365) | U9: =IF(R9="","",IF(T9<=0.6,"0-6 meses",IF(T9<=2,"7-23 meses",IF(T9<=5,"24-59 meses",IF(T9>5,"Mayor a 5 años"))))) | AA9: =IF(ISBLANK(Z9),"ERROR",IF(AND(Z9>=12.5,Z9<=35),"Adecuado",IF(AND(Z9<11.5,Z9>=9),"Desnutrición aguda severa",IF(AND(Z9>=11.5,Z9<12.5),"Desnutrición aguda moderada",IF(AND(Z9>=6,Z9<9),"Referencia valoración médica",IF(Z9<6,"Dato inválido",IF(Z9>35,"Dato inválido"))))))) -> ERROR | AE9: =IF(ISBLANK(AD9),"ERROR",IF(AND(AD9>3,AD9<5),"Obesidad",IF(AND(AD9>2,AD9<=3),"Sobrepeso",IF(AND(AD9<=2,AD9>=-2),"Adecuado",IF(AND(AD9>=-3,AD9<-2),"Desnutrición aguda moderada",IF(AND(AD9<-3,AD9>-5),"Desnutrición aguda severa",IF(AD9<=-5,"Dato inválido",IF(AD9>=5,"Dato inválido")))))))) -> ERROR | AR9: =IF(D9="","",TEXT(S9,"MMMM")) | AS9: =IF(F9="","",TEXT(S9,"YYYY")) | AT9: =B9&" - "&E9 -> - | AU9: =IFERROR(VLOOKUP(B9,adm!$C$2:$E$36,3,FALSE),"")
A10: 9 | N10: =AU10&R10&A10 -> 9 | T10: =IF(R10="","",(S10-R10)/365) | U10: =IF(R10="","",IF(T10<=0.6,"0-6 meses",IF(T10<=2,"7-23 meses",IF(T10<=5,"24-59 meses",IF(T10>5,"Mayor a 5 años"))))) | AA10: =IF(ISBLANK(Z10),"ERROR",IF(AND(Z10>=12.5,Z10<=35),"Adecuado",IF(AND(Z10<11.5,Z10>=9),"Desnutrición aguda severa",IF(AND(Z10>=11.5,Z10<12.5),"Desnutrición aguda moderada",IF(AND(Z10>=6,Z10<9),"Referencia valoración médica",IF(Z10<6,"Dato inválido",IF(Z10>35,"Dato inválido"))))))) -> ERROR | AE10: =IF(ISBLANK(AD10),"ERROR",IF(AND(AD10>3,AD10<5),"Obesidad",IF(AND(AD10>2,AD10<=3),"Sobrepeso",IF(AND(AD10<=2,AD10>=-2),"Adecuado",IF(AND(AD10>=-3,AD10<-2),"Desnutrición aguda moderada",IF(AND(AD10<-3,AD10>-5),"Desnutrición aguda severa",IF(AD10<=-5,"Dato inválido",IF(AD10>=5,"Dato inválido")))))))) -> ERROR | AR10: =IF(D10="","",TEXT(S10,"MMMM")) | AS10: =IF(F10="","",TEXT(S10,"YYYY")) | AT10: =B10&" - "&E10 -> - | AU10: =IFERROR(VLOOKUP(B10,adm!$C$2:$E$36,3,FALSE),"")
A11: 10 | N11: =AU11&R11&A11 -> 10 | T11: =IF(R11="","",(S11-R11)/365) | U11: =IF(R11="","",IF(T11<=0.6,"0-6 meses",IF(T11<=2,"7-23 meses",IF(T11<=5,"24-59 meses",IF(T11>5,"Mayor a 5 años"))))) | AA11: =IF(ISBLANK(Z11),"ERROR",IF(AND(Z11>=12.5,Z11<=35),"Adecuado",IF(AND(Z11<11.5,Z11>=9),"Desnutrición aguda severa",IF(AND(Z11>=11.5,Z11<12.5),"Desnutrición aguda moderada",IF(AND(Z11>=6,Z11<9),"Referencia valoración médica",IF(Z11<6,"Dato inválido",IF(Z11>35,"Dato inválido"))))))) -> ERROR | AE11: =IF(ISBLANK(AD11),"ERROR",IF(AND(AD11>3,AD11<5),"Obesidad",IF(AND(AD11>2,AD11<=3),"Sobrepeso",IF(AND(AD11<=2,AD11>=-2),"Adecuado",IF(AND(AD11>=-3,AD11<-2),"Desnutrición aguda moderada",IF(AND(AD11<-3,AD11>-5),"Desnutrición aguda severa",IF(AD11<=-5,"Dato inválido",IF(AD11>=5,"Dato inválido")))))))) -> ERROR | AR11: =IF(D11="","",TEXT(S11,"MMMM")) | AS11: =IF(F11="","",TEXT(S11,"YYYY")) | AT11: =B11&" - "&E11 -> - | AU11: =IFERROR(VLOOKUP(B11,adm!$C$2:$E$36,3,FALSE),"")
A12: 11 | N12: =AU12&R12&A12 -> 11 | T12: =IF(R12="","",(S12-R12)/365) | U12: =IF(R12="","",IF(T12<=0.6,"0-6 meses",IF(T12<=2,"7-23 meses",IF(T12<=5,"24-59 meses",IF(T12>5,"Mayor a 5 años"))))) | AA12: =IF(ISBLANK(Z12),"ERROR",IF(AND(Z12>=12.5,Z12<=35),"Adecuado",IF(AND(Z12<11.5,Z12>=9),"Desnutrición aguda severa",IF(AND(Z12>=11.5,Z12<12.5),"Desnutrición aguda moderada",IF(AND(Z12>=6,Z12<9),"Referencia valoración médica",IF(Z12<6,"Dato inválido",IF(Z12>35,"Dato inválido"))))))) -> ERROR | AE12: =IF(ISBLANK(AD12),"ERROR",IF(AND(AD12>3,AD12<5),"Obesidad",IF(AND(AD12>2,AD12<=3),"Sobrepeso",IF(AND(AD12<=2,AD12>=-2),"Adecuado",IF(AND(AD12>=-3,AD12<-2),"Desnutrición aguda moderada",IF(AND(AD12<-3,AD12>-5),"Desnutrición aguda severa",IF(AD12<=-5,"Dato inválido",IF(AD12>=5,"Dato inválido")))))))) -> ERROR | AR12: =IF(D12="","",TEXT(S12,"MMMM")) | AS12: =IF(F12="","",TEXT(S12,"YYYY")) | AT12: =B12&" - "&E12 -> - | AU12: =IFERROR(VLOOKUP(B12,adm!$C$2:$E$36,3,FALSE),"")
A13: 12 | N13: =AU13&R13&A13 -> 12 | T13: =IF(R13="","",(S13-R13)/365) | U13: =IF(R13="","",IF(T13<=0.6,"0-6 meses",IF(T13<=2,"7-23 meses",IF(T13<=5,"24-59 meses",IF(T13>5,"Mayor a 5 años"))))) | AA13: =IF(ISBLANK(Z13),"ERROR",IF(AND(Z13>=12.5,Z13<=35),"Adecuado",IF(AND(Z13<11.5,Z13>=9),"Desnutrición aguda severa",IF(AND(Z13>=11.5,Z13<12.5),"Desnutrición aguda moderada",IF(AND(Z13>=6,Z13<9),"Referencia valoración médica",IF(Z13<6,"Dato inválido",IF(Z13>35,"Dato inválido"))))))) -> ERROR | AE13: =IF(ISBLANK(AD13),"ERROR",IF(AND(AD13>3,AD13<5),"Obesidad",IF(AND(AD13>2,AD13<=3),"Sobrepeso",IF(AND(AD13<=2,AD13>=-2),"Adecuado",IF(AND(AD13>=-3,AD13<-2),"Desnutrición aguda moderada",IF(AND(AD13<-3,AD13>-5),"Desnutrición aguda severa",IF(AD13<=-5,"Dato inválido",IF(AD13>=5,"Dato inválido")))))))) -> ERROR | AR13: =IF(D13="","",TEXT(S13,"MMMM")) | AS13: =IF(F13="","",TEXT(S13,"YYYY")) | AT13: =B13&" - "&E13 -> - | AU13: =IFERROR(VLOOKUP(B13,adm!$C$2:$E$36,3,FALSE),"")
... A15: 14 | N15: =AU15&R15&A15 -> 14 | T15: =IF(R15="","",(S15-R15)/365) | U15: =IF(R15="","",IF(T15<=0.6,"0-6 meses",IF(T15<=2,"7-23 meses",IF(T15<=5,"24-59 meses",IF(T15>5,"Mayor a 5 años"))))) | AA15: =IF(ISBLANK(Z15),"ERROR",IF(AND(Z15>=12.5,Z15<=35),"Adecuado",IF(AND(Z15<11.5,Z15>=9),"Desnutrición aguda severa",IF(AND(Z15>=11.5,Z15<12.5),"Desnutrición aguda moderada",IF(AND(Z15>=6,Z15<9),"Referencia valoración médica",IF(Z15<6,"Dato inválido",IF(Z15>35,"Dato inválido"))))))) -> ERROR | AE15: =IF(ISBLANK(AD15),"ERROR",IF(AND(AD15>3,AD15<5),"Obesidad",IF(AND(AD15>2,AD15<=3),"Sobrepeso",IF(AND(AD15<=2,AD15>=-2),"Adecuado",IF(AND(AD15>=-3,AD15<-2),"Desnutrición aguda moderada",IF(AND(AD15<-3,AD15>-5),"Desnutrición aguda severa",IF(AD15<=-5,"Dato inválido",IF(AD15>=5,"Dato inválido")))))))) -> ERROR | AR15: =IF(D15="","",TEXT(S15,"MMMM")) | AS15: =IF(F15="","",TEXT(S15,"YYYY")) | AT15: =B15&" - "&E15 -> - | AU15: =IFERROR(VLOOKUP(B15,adm!$C$2:$E$36,3,FALSE),"")
A16: 15 | N16: =AU16&R16&A16 -> 15 | T16: =IF(R16="","",(S16-R16)/365) | U16: =IF(R16="","",IF(T16<=0.6,"0-6 meses",IF(T16<=2,"7-23 meses",IF(T16<=5,"24-59 meses",IF(T16>5,"Mayor a 5 años"))))) | AA16: =IF(ISBLANK(Z16),"ERROR",IF(AND(Z16>=12.5,Z16<=35),"Adecuado",IF(AND(Z16<11.5,Z16>=9),"Desnutrición aguda severa",IF(AND(Z16>=11.5,Z16<12.5),"Desnutrición aguda moderada",IF(AND(Z16>=6,Z16<9),"Referencia valoración médica",IF(Z16<6,"Dato inválido",IF(Z16>35,"Dato inválido"))))))) -> ERROR | AE16: =IF(ISBLANK(AD17),"ERROR",IF(AND(AD17>3,AD17<5),"Obesidad",IF(AND(AD17>2,AD17<=3),"Sobrepeso",IF(AND(AD17<=2,AD17>=-2),"Adecuado",IF(AND(AD17>=-3,AD17<-2),"Desnutrición aguda moderada",IF(AND(AD17<-3,AD17>-5),"Desnutrición aguda severa",IF(AD17<=-5,"Dato inválido",IF(AD17>=5,"Dato inválido")))))))) -> ERROR | AR16: =IF(D16="","",TEXT(S16,"MMMM")) | AS16: =IF(F16="","",TEXT(S16,"YYYY")) | AT16: =B16&" - "&E16 -> - | AU16: =IFERROR(VLOOKUP(B16,adm!$C$2:$E$36,3,FALSE),"")
A17: 16 | N17: =AU17&R17&A17 -> 16 | T17: =IF(R17="","",(S17-R17)/365) | U17: =IF(R17="","",IF(T17<=0.6,"0-6 meses",IF(T17<=2,"7-23 meses",IF(T17<=5,"24-59 meses",IF(T17>5,"Mayor a 5 años"))))) | AA17: =IF(ISBLANK(Z17),"ERROR",IF(AND(Z17>=12.5,Z17<=35),"Adecuado",IF(AND(Z17<11.5,Z17>=9),"Desnutrición aguda severa",IF(AND(Z17>=11.5,Z17<12.5),"Desnutrición aguda moderada",IF(AND(Z17>=6,Z17<9),"Referencia valoración médica",IF(Z17<6,"Dato inválido",IF(Z17>35,"Dato inválido"))))))) -> ERROR | AE17: =IF(ISBLANK(AD18),"ERROR",IF(AND(AD18>3,AD18<5),"Obesidad",IF(AND(AD18>2,AD18<=3),"Sobrepeso",IF(AND(AD18<=2,AD18>=-2),"Adecuado",IF(AND(AD18>=-3,AD18<-2),"Desnutrición aguda moderada",IF(AND(AD18<-3,AD18>-5),"Desnutrición aguda severa",IF(AD18<=-5,"Dato inválido",IF(AD18>=5,"Dato inválido")))))))) -> ERROR | AR17: =IF(D17="","",TEXT(S17,"MMMM")) | AS17: =IF(F17="","",TEXT(S17,"YYYY")) | AT17: =B17&" - "&E17 -> - | AU17: =IFERROR(VLOOKUP(B17,adm!$C$2:$E$36,3,FALSE),"")
A18: 17 | N18: =AU18&R18&A18 -> 17 | T18: =IF(R18="","",(S18-R18)/365) | U18: =IF(R18="","",IF(T18<=0.6,"0-6 meses",IF(T18<=2,"7-23 meses",IF(T18<=5,"24-59 meses",IF(T18>5,"Mayor a 5 años"))))) | AA18: =IF(ISBLANK(Z18),"ERROR",IF(AND(Z18>=12.5,Z18<=35),"Adecuado",IF(AND(Z18<11.5,Z18>=9),"Desnutrición aguda severa",IF(AND(Z18>=11.5,Z18<12.5),"Desnutrición aguda moderada",IF(AND(Z18>=6,Z18<9),"Referencia valoración médica",IF(Z18<6,"Dato inválido",IF(Z18>35,"Dato inválido"))))))) -> ERROR | AE18: =IF(ISBLANK(AD18),"ERROR",IF(AND(AD18>3,AD18<5),"Obesidad",IF(AND(AD18>2,AD18<=3),"Sobrepeso",IF(AND(AD18<=2,AD18>=-2),"Adecuado",IF(AND(AD18>=-3,AD18<-2),"Desnutrición aguda moderada",IF(AND(AD18<-3,AD18>-5),"Desnutrición aguda severa",IF(AD18<=-5,"Dato inválido",IF(AD18>=5,"Dato inválido")))))))) -> ERROR | AR18: =IF(D18="","",TEXT(S18,"MMMM")) | AS18: =IF(F18="","",TEXT(S18,"YYYY")) | AT18: =B18&" - "&E18 -> - | AU18: =IFERROR(VLOOKUP(B18,adm!$C$2:$E$36,3,FALSE),"")
A19: 18 | N19: =AU19&R19&A19 -> 18 | T19: =IF(R19="","",(S19-R19)/365) | U19: =IF(R19="","",IF(T19<=0.6,"0-6 meses",IF(T19<=2,"7-23 meses",IF(T19<=5,"24-59 meses",IF(T19>5,"Mayor a 5 años"))))) | AA19: =IF(ISBLANK(Z19),"ERROR",IF(AND(Z19>=12.5,Z19<=35),"Adecuado",IF(AND(Z19<11.5,Z19>=9),"Desnutrición aguda severa",IF(AND(Z19>=11.5,Z19<12.5),"Desnutrición aguda moderada",IF(AND(Z19>=6,Z19<9),"Referencia valoración médica",IF(Z19<6,"Dato inválido",IF(Z19>35,"Dato inválido"))))))) -> ERROR | AE19: =IF(ISBLANK(AD19),"ERROR",IF(AND(AD19>3,AD19<5),"Obesidad",IF(AND(AD19>2,AD19<=3),"Sobrepeso",IF(AND(AD19<=2,AD19>=-2),"Adecuado",IF(AND(AD19>=-3,AD19<-2),"Desnutrición aguda moderada",IF(AND(AD19<-3,AD19>-5),"Desnutrición aguda severa",IF(AD19<=-5,"Dato inválido",IF(AD19>=5,"Dato inválido")))))))) -> ERROR | AR19: =IF(D19="","",TEXT(S19,"MMMM")) | AS19: =IF(F19="","",TEXT(S19,"YYYY")) | AT19: =B19&" - "&E19 -> - | AU19: =IFERROR(VLOOKUP(B19,adm!$C$2:$E$36,3,FALSE),"")
A20: 19 | N20: =AU20&R20&A20 -> 19 | T20: =IF(R20="","",(S20-R20)/365) | U20: =IF(R20="","",IF(T20<=0.6,"0-6 meses",IF(T20<=2,"7-23 meses",IF(T20<=5,"24-59 meses",IF(T20>5,"Mayor a 5 años"))))) | AA20: =IF(ISBLANK(Z20),"ERROR",IF(AND(Z20>=12.5,Z20<=35),"Adecuado",IF(AND(Z20<11.5,Z20>=9),"Desnutrición aguda severa",IF(AND(Z20>=11.5,Z20<12.5),"Desnutrición aguda moderada",IF(AND(Z20>=6,Z20<9),"Referencia valoración médica",IF(Z20<6,"Dato inválido",IF(Z20>35,"Dato inválido"))))))) -> ERROR | AE20: =IF(ISBLANK(AD20),"ERROR",IF(AND(AD20>3,AD20<5),"Obesidad",IF(AND(AD20>2,AD20<=3),"Sobrepeso",IF(AND(AD20<=2,AD20>=-2),"Adecuado",IF(AND(AD20>=-3,AD20<-2),"Desnutrición aguda moderada",IF(AND(AD20<-3,AD20>-5),"Desnutrición aguda severa",IF(AD20<=-5,"Dato inválido",IF(AD20>=5,"Dato inválido")))))))) -> ERROR | AR20: =IF(D20="","",TEXT(S20,"MMMM")) | AS20: =IF(F20="","",TEXT(S20,"YYYY")) | AT20: =B20&" - "&E20 -> - | AU20: =IFERROR(VLOOKUP(B20,adm!$C$2:$E$36,3,FALSE),"")
A21: 20 | N21: =AU21&R21&A21 -> 20 | T21: =IF(R21="","",(S21-R21)/365) | U21: =IF(R21="","",IF(T21<=0.6,"0-6 meses",IF(T21<=2,"7-23 meses",IF(T21<=5,"24-59 meses",IF(T21>5,"Mayor a 5 años"))))) | AA21: =IF(ISBLANK(Z21),"ERROR",IF(AND(Z21>=12.5,Z21<=35),"Adecuado",IF(AND(Z21<11.5,Z21>=9),"Desnutrición aguda severa",IF(AND(Z21>=11.5,Z21<12.5),"Desnutrición aguda moderada",IF(AND(Z21>=6,Z21<9),"Referencia valoración médica",IF(Z21<6,"Dato inválido",IF(Z21>35,"Dato inválido"))))))) -> ERROR | AE21: =IF(ISBLANK(AD21),"ERROR",IF(AND(AD21>3,AD21<5),"Obesidad",IF(AND(AD21>2,AD21<=3),"Sobrepeso",IF(AND(AD21<=2,AD21>=-2),"Adecuado",IF(AND(AD21>=-3,AD21<-2),"Desnutrición aguda moderada",IF(AND(AD21<-3,AD21>-5),"Desnutrición aguda severa",IF(AD21<=-5,"Dato inválido",IF(AD21>=5,"Dato inválido")))))))) -> ERROR | AR21: =IF(D21="","",TEXT(S21,"MMMM")) | AS21: =IF(F21="","",TEXT(S21,"YYYY")) | AT21: =B21&" - "&E21 -> - | AU21: =IFERROR(VLOOKUP(B21,adm!$C$2:$E$36,3,FALSE),"")
A22: 21 | N22: =AU22&R22&A22 -> 21 | T22: =IF(R22="","",(S22-R22)/365) | U22: =IF(R22="","",IF(T22<=0.6,"0-6 meses",IF(T22<=2,"7-23 meses",IF(T22<=5,"24-59 meses",IF(T22>5,"Mayor a 5 años"))))) | AA22: =IF(ISBLANK(Z22),"ERROR",IF(AND(Z22>=12.5,Z22<=35),"Adecuado",IF(AND(Z22<11.5,Z22>=9),"Desnutrición aguda severa",IF(AND(Z22>=11.5,Z22<12.5),"Desnutrición aguda moderada",IF(AND(Z22>=6,Z22<9),"Referencia valoración médica",IF(Z22<6,"Dato inválido",IF(Z22>35,"Dato inválido"))))))) -> ERROR | AE22: =IF(ISBLANK(AD22),"ERROR",IF(AND(AD22>3,AD22<5),"Obesidad",IF(AND(AD22>2,AD22<=3),"Sobrepeso",IF(AND(AD22<=2,AD22>=-2),"Adecuado",IF(AND(AD22>=-3,AD22<-2),"Desnutrición aguda moderada",IF(AND(AD22<-3,AD22>-5),"Desnutrición aguda severa",IF(AD22<=-5,"Dato inválido",IF(AD22>=5,"Dato inválido")))))))) -> ERROR | AR22: =IF(D22="","",TEXT(S22,"MMMM")) | AS22: =IF(F22="","",TEXT(S22,"YYYY")) | AT22: =B22&" - "&E22 -> - | AU22: =IFERROR(VLOOKUP(B22,adm!$C$2:$E$36,3,FALSE),"")
A23: 22 | N23: =AU23&R23&A23 -> 22 | T23: =IF(R23="","",(S23-R23)/365) | U23: =IF(R23="","",IF(T23<=0.6,"0-6 meses",IF(T23<=2,"7-23 meses",IF(T23<=5,"24-59 meses",IF(T23>5,"Mayor a 5 años"))))) | AA23: =IF(ISBLANK(Z23),"ERROR",IF(AND(Z23>=12.5,Z23<=35),"Adecuado",IF(AND(Z23<11.5,Z23>=9),"Desnutrición aguda severa",IF(AND(Z23>=11.5,Z23<12.5),"Desnutrición aguda moderada",IF(AND(Z23>=6,Z23<9),"Referencia valoración médica",IF(Z23<6,"Dato inválido",IF(Z23>35,"Dato inválido"))))))) -> ERROR | AE23: =IF(ISBLANK(AD23),"ERROR",IF(AND(AD23>3,AD23<5),"Obesidad",IF(AND(AD23>2,AD23<=3),"Sobrepeso",IF(AND(AD23<=2,AD23>=-2),"Adecuado",IF(AND(AD23>=-3,AD23<-2),"Desnutrición aguda moderada",IF(AND(AD23<-3,AD23>-5),"Desnutrición aguda severa",IF(AD23<=-5,"Dato inválido",IF(AD23>=5,"Dato inválido")))))))) -> ERROR | AR23: =IF(D23="","",TEXT(S23,"MMMM")) | AS23: =IF(F23="","",TEXT(S23,"YYYY")) | AT23: =B23&" - "&E23 -> - | AU23: =IFERROR(VLOOKUP(B23,adm!$C$2:$E$36,3,FALSE),"")
A24: 23 | N24: =AU24&R24&A24 -> 23 | T24: =IF(R24="","",(S24-R24)/365) | U24: =IF(R24="","",IF(T24<=0.6,"0-6 meses",IF(T24<=2,"7-23 meses",IF(T24<=5,"24-59 meses",IF(T24>5,"Mayor a 5 años"))))) | AA24: =IF(ISBLANK(Z24),"ERROR",IF(AND(Z24>=12.5,Z24<=35),"Adecuado",IF(AND(Z24<11.5,Z24>=9),"Desnutrición aguda severa",IF(AND(Z24>=11.5,Z24<12.5),"Desnutrición aguda moderada",IF(AND(Z24>=6,Z24<9),"Referencia valoración médica",IF(Z24<6,"Dato inválido",IF(Z24>35,"Dato inválido"))))))) -> ERROR | AE24: =IF(ISBLANK(AD24),"ERROR",IF(AND(AD24>3,AD24<5),"Obesidad",IF(AND(AD24>2,AD24<=3),"Sobrepeso",IF(AND(AD24<=2,AD24>=-2),"Adecuado",IF(AND(AD24>=-3,AD24<-2),"Desnutrición aguda moderada",IF(AND(AD24<-3,AD24>-5),"Desnutrición aguda severa",IF(AD24<=-5,"Dato inválido",IF(AD24>=5,"Dato inválido")))))))) -> ERROR | AR24: =IF(D24="","",TEXT(S24,"MMMM")) | AS24: =IF(F24="","",TEXT(S24,"YYYY")) | AT24: =B24&" - "&E24 -> - | AU24: =IFERROR(VLOOKUP(B24,adm!$C$2:$E$36,3,FALSE),"")
A25: 24 | N25: =AU25&R25&A25 -> 24 | T25: =IF(R25="","",(S25-R25)/365) | U25: =IF(R25="","",IF(T25<=0.6,"0-6 meses",IF(T25<=2,"7-23 meses",IF(T25<=5,"24-59 meses",IF(T25>5,"Mayor a 5 años"))))) | AA25: =IF(ISBLANK(Z25),"ERROR",IF(AND(Z25>=12.5,Z25<=35),"Adecuado",IF(AND(Z25<11.5,Z25>=9),"Desnutrición aguda severa",IF(AND(Z25>=11.5,Z25<12.5),"Desnutrición aguda moderada",IF(AND(Z25>=6,Z25<9),"Referencia valoración médica",IF(Z25<6,"Dato inválido",IF(Z25>35,"Dato inválido"))))))) -> ERROR | AE25: =IF(ISBLANK(AD25),"ERROR",IF(AND(AD25>3,AD25<5),"Obesidad",IF(AND(AD25>2,AD25<=3),"Sobrepeso",IF(AND(AD25<=2,AD25>=-2),"Adecuado",IF(AND(AD25>=-3,AD25<-2),"Desnutrición aguda moderada",IF(AND(AD25<-3,AD25>-5),"Desnutrición aguda severa",IF(AD25<=-5,"Dato inválido",IF(AD25>=5,"Dato inválido")))))))) -> ERROR | AR25: =IF(D25="","",TEXT(S25,"MMMM")) | AS25: =IF(F25="","",TEXT(S25,"YYYY")) | AT25: =B25&" - "&E25 -> - | AU25: =IFERROR(VLOOKUP(B25,adm!$C$2:$E$36,3,FALSE),"")
A26: 25 | N26: =AU26&R26&A26 -> 25 | T26: =IF(R26="","",(S26-R26)/365) | U26: =IF(R26="","",IF(T26<=0.6,"0-6 meses",IF(T26<=2,"7-23 meses",IF(T26<=5,"24-59 meses",IF(T26>5,"Mayor a 5 años"))))) | AA26: =IF(ISBLANK(Z26),"ERROR",IF(AND(Z26>=12.5,Z26<=35),"Adecuado",IF(AND(Z26<11.5,Z26>=9),"Desnutrición aguda severa",IF(AND(Z26>=11.5,Z26<12.5),"Desnutrición aguda moderada",IF(AND(Z26>=6,Z26<9),"Referencia valoración médica",IF(Z26<6,"Dato inválido",IF(Z26>35,"Dato inválido"))))))) -> ERROR | AE26: =IF(ISBLANK(AD26),"ERROR",IF(AND(AD26>3,AD26<5),"Obesidad",IF(AND(AD26>2,AD26<=3),"Sobrepeso",IF(AND(AD26<=2,AD26>=-2),"Adecuado",IF(AND(AD26>=-3,AD26<-2),"Desnutrición aguda moderada",IF(AND(AD26<-3,AD26>-5),"Desnutrición aguda severa",IF(AD26<=-5,"Dato inválido",IF(AD26>=5,"Dato inválido")))))))) -> ERROR | AR26: =IF(D26="","",TEXT(S26,"MMMM")) | AS26: =IF(F26="","",TEXT(S26,"YYYY")) | AT26: =B26&" - "&E26 -> - | AU26: =IFERROR(VLOOKUP(B26,adm!$C$2:$E$36,3,FALSE),"")
A27: 26 | N27: =AU27&R27&A27 -> 26 | T27: =IF(R27="","",(S27-R27)/365) | U27: =IF(R27="","",IF(T27<=0.6,"0-6 meses",IF(T27<=2,"7-23 meses",IF(T27<=5,"24-59 meses",IF(T27>5,"Mayor a 5 años"))))) | AA27: =IF(ISBLANK(Z27),"ERROR",IF(AND(Z27>=12.5,Z27<=35),"Adecuado",IF(AND(Z27<11.5,Z27>=9),"Desnutrición aguda severa",IF(AND(Z27>=11.5,Z27<12.5),"Desnutrición aguda moderada",IF(AND(Z27>=6,Z27<9),"Referencia valoración médica",IF(Z27<6,"Dato inválido",IF(Z27>35,"Dato inválido"))))))) -> ERROR | AE27: =IF(ISBLANK(AD27),"ERROR",IF(AND(AD27>3,AD27<5),"Obesidad",IF(AND(AD27>2,AD27<=3),"Sobrepeso",IF(AND(AD27<=2,AD27>=-2),"Adecuado",IF(AND(AD27>=-3,AD27<-2),"Desnutrición aguda moderada",IF(AND(AD27<-3,AD27>-5),"Desnutrición aguda severa",IF(AD27<=-5,"Dato inválido",IF(AD27>=5,"Dato inválido")))))))) -> ERROR | AR27: =IF(D27="","",TEXT(S27,"MMMM")) | AS27: =IF(F27="","",TEXT(S27,"YYYY")) | AT27: =B27&" - "&E27 -> - | AU27: =IFERROR(VLOOKUP(B27,adm!$C$2:$E$36,3,FALSE),"")
A28: 27 | N28: =AU28&R28&A28 -> 27 | T28: =IF(R28="","",(S28-R28)/365) | U28: =IF(R28="","",IF(T28<=0.6,"0-6 meses",IF(T28<=2,"7-23 meses",IF(T28<=5,"24-59 meses",IF(T28>5,"Mayor a 5 años"))))) | AA28: =IF(ISBLANK(Z28),"ERROR",IF(AND(Z28>=12.5,Z28<=35),"Adecuado",IF(AND(Z28<11.5,Z28>=9),"Desnutrición aguda severa",IF(AND(Z28>=11.5,Z28<12.5),"Desnutrición aguda moderada",IF(AND(Z28>=6,Z28<9),"Referencia valoración médica",IF(Z28<6,"Dato inválido",IF(Z28>35,"Dato inválido"))))))) -> ERROR | AE28: =IF(ISBLANK(AD28),"ERROR",IF(AND(AD28>3,AD28<5),"Obesidad",IF(AND(AD28>2,AD28<=3),"Sobrepeso",IF(AND(AD28<=2,AD28>=-2),"Adecuado",IF(AND(AD28>=-3,AD28<-2),"Desnutrición aguda moderada",IF(AND(AD28<-3,AD28>-5),"Desnutrición aguda severa",IF(AD28<=-5,"Dato inválido",IF(AD28>=5,"Dato inválido")))))))) -> ERROR | AR28: =IF(D28="","",TEXT(S28,"MMMM")) | AS28: =IF(F28="","",TEXT(S28,"YYYY")) | AT28: =B28&" - "&E28 -> - | AU28: =IFERROR(VLOOKUP(B28,adm!$C$2:$E$36,3,FALSE),"")
A29: 28 | N29: =AU29&R29&A29 -> 28 | T29: =IF(R29="","",(S29-R29)/365) | U29: =IF(R29="","",IF(T29<=0.6,"0-6 meses",IF(T29<=2,"7-23 meses",IF(T29<=5,"24-59 meses",IF(T29>5,"Mayor a 5 años"))))) | AA29: =IF(ISBLANK(Z29),"ERROR",IF(AND(Z29>=12.5,Z29<=35),"Adecuado",IF(AND(Z29<11.5,Z29>=9),"Desnutrición aguda severa",IF(AND(Z29>=11.5,Z29<12.5),"Desnutrición aguda moderada",IF(AND(Z29>=6,Z29<9),"Referencia valoración médica",IF(Z29<6,"Dato inválido",IF(Z29>35,"Dato inválido"))))))) -> ERROR | AE29: =IF(ISBLANK(AD29),"ERROR",IF(AND(AD29>3,AD29<5),"Obesidad",IF(AND(AD29>2,AD29<=3),"Sobrepeso",IF(AND(AD29<=2,AD29>=-2),"Adecuado",IF(AND(AD29>=-3,AD29<-2),"Desnutrición aguda moderada",IF(AND(AD29<-3,AD29>-5),"Desnutrición aguda severa",IF(AD29<=-5,"Dato inválido",IF(AD29>=5,"Dato inválido")))))))) -> ERROR | AR29: =IF(D29="","",TEXT(S29,"MMMM")) | AS29: =IF(F29="","",TEXT(S29,"YYYY")) | AT29: =B29&" - "&E29 -> - | AU29: =IFERROR(VLOOKUP(B29,adm!$C$2:$E$36,3,FALSE),"")
... A994: 993 | N994: =AU994&R994&A994 -> 993 | T994: =IF(R994="","",(S994-R994)/365) | U994: =IF(R994="","",IF(T994<=0.6,"0-6 meses",IF(T994<=2,"7-23 meses",IF(T994<=5,"24-59 meses",IF(T994>5,"Mayor a 5 años"))))) | AA994: =IF(ISBLANK(Z994),"ERROR",IF(AND(Z994>=12.5,Z994<=35),"Adecuado",IF(AND(Z994<11.5,Z994>=9),"Desnutrición aguda severa",IF(AND(Z994>=11.5,Z994<12.5),"Desnutrición aguda moderada",IF(AND(Z994>=6,Z994<9),"Referencia valoración médica",IF(Z994<6,"Dato inválido",IF(Z994>35,"Dato inválido"))))))) -> ERROR | AE994: =IF(ISBLANK(AD994),"ERROR",IF(AND(AD994>3,AD994<5),"Obesidad",IF(AND(AD994>2,AD994<=3),"Sobrepeso",IF(AND(AD994<=2,AD994>=-2),"Adecuado",IF(AND(AD994>=-3,AD994<-2),"Desnutrición aguda moderada",IF(AND(AD994<-3,AD994>-5),"Desnutrición aguda severa",IF(AD994<=-5,"Dato inválido",IF(AD994>=5,"Dato inválido")))))))) -> ERROR | AR994: =IF(D994="","",TEXT(S994,"MMMM")) | AS994: =IF(F994="","",TEXT(S994,"YYYY")) | AT994: =B994&" - "&E994 -> - | AU994: =IFERROR(VLOOKUP(B994,adm!$C$2:$E$36,3,FALSE),"")

Sheet 2. SAMAN EMBARAZADAS
A1: # | B1: DIOCESIS | C1: ESTADO | D1: MUNICIPIO | E1: PARROQUIA CIVIL | F1: PARROQUIA ECLESIAL / CENTRO CENTINELA | G1: SECTOR O COMUNIDAD | H1: GRUPO ETNICO | I1: Fecha de Medición dd/mm/aaaa | J1: TIPO DE INGRESO | K1: NOMBRE | L1: APELLIDO | M1: CÉDULA DE IDENTIDAD (ingrese números sin espacios) | N1: Fecha de Nacimiento dd/mm/aaaa | O1: EMBARAZADA ó LACTANTE | P1: SEMANA DE GESTACIÓN | Q1: EDAD | R1: EDEMA | S1: PESO (kg) | T1: TALLA (cm) | U1: IMC | V1: CLASIFICACIÓN NUTRICIONAL | W1: BRAZO (CM) | X1: CLASIFICACIÓN NUTRICIONAL PB | Y1: Desparasitada | Z1: Tratamiento suministrado Según Protocolo Cáritas | AA1: CANTIDAD | AB1: Situación de Salida | AC1: Observaciones | AD1: MES | AE1: AÑO | AF1: CENTRO
A2: 1 | Q2: =IF(N2="","",((YEAR(I2)-YEAR(N2))*12+MONTH(I2)-MONTH(N2))/12) | U2: =(S2/((T2/100)*(T2/100))) -> #DIV/0! | V2: =IF(U2<18.5,"Bajo Peso ",IF(AND(U2>=18.5,U2<25),"Adecuado ",IF(AND(U2>=25,U2<30),"Sobrepeso ",IF(U2>=30,"Obesidad","Obesidad")))) -> #DIV/0! | X2: =IF(ISBLANK(W2),"ERROR",IF(AND(W2>=23,W2<=50),"Peso Normal",IF(AND(W2<23,W2>=15),"Bajo peso",IF(W2<15,"Dato inválido",IF(W2>50,"Dato inválido"))))) -> ERROR | AD2: =IF(I2="","",TEXT(I2,"MMMM")) | AE2: =IF(I2="","",TEXT(I2,"YYYY")) | AF2: =Tabla3[[#This Row],[DIOCESIS]]&" "&"-"&" "&Tabla3[[#This Row],[PARROQUIA ECLESIAL / CENTRO CENTINELA]] -> -
A3: =A2+1 -> 2 | Q3: =IF(N3="","",((YEAR(I3)-YEAR(N3))*12+MONTH(I3)-MONTH(N3))/12) | U3: =(S3/((T3/100)*(T3/100))) -> #DIV/0! | V3: =IF(U3<18.5,"Bajo Peso ",IF(AND(U3>=18.5,U3<25),"Adecuado ",IF(AND(U3>=25,U3<30),"Sobrepeso ",IF(U3>=30,"Obesidad","Obesidad")))) -> #DIV/0! | X3: =IF(ISBLANK(W3),"ERROR",IF(AND(W3>=23,W3<=50),"Peso Normal",IF(AND(W3<23,W3>=15),"Bajo peso",IF(W3<15,"Dato inválido",IF(W3>50,"Dato inválido"))))) -> ERROR | AD3: =IF(I3="","",TEXT(I3,"MMMM")) | AE3: =IF(I3="","",TEXT(I3,"YYYY")) | AF3: =Tabla3[[#This Row],[DIOCESIS]]&" "&"-"&" "&Tabla3[[#This Row],[PARROQUIA ECLESIAL / CENTRO CENTINELA]] -> -
A4: =A3+1 -> 3 | Q4: =IF(N4="","",((YEAR(I4)-YEAR(N4))*12+MONTH(I4)-MONTH(N4))/12) | U4: =(S4/((T4/100)*(T4/100))) -> #DIV/0! | V4: =IF(U4<18.5,"Bajo Peso ",IF(AND(U4>=18.5,U4<25),"Adecuado ",IF(AND(U4>=25,U4<30),"Sobrepeso ",IF(U4>=30,"Obesidad","Obesidad")))) -> #DIV/0! | X4: =IF(ISBLANK(W4),"ERROR",IF(AND(W4>=23,W4<=50),"Peso Normal",IF(AND(W4<23,W4>=15),"Bajo peso",IF(W4<15,"Dato inválido",IF(W4>50,"Dato inválido"))))) -> ERROR | AD4: =IF(I4="","",TEXT(I4,"MMMM")) | AE4: =IF(I4="","",TEXT(I4,"YYYY")) | AF4: =Tabla3[[#This Row],[DIOCESIS]]&" "&"-"&" "&Tabla3[[#This Row],[PARROQUIA ECLESIAL / CENTRO CENTINELA]] -> -
A5: =A4+1 -> 4 | Q5: =IF(N5="","",((YEAR(I5)-YEAR(N5))*12+MONTH(I5)-MONTH(N5))/12) | U5: =(S5/((T5/100)*(T5/100))) -> #DIV/0! | V5: =IF(U5<18.5,"Bajo Peso ",IF(AND(U5>=18.5,U5<25),"Adecuado ",IF(AND(U5>=25,U5<30),"Sobrepeso ",IF(U5>=30,"Obesidad","Obesidad")))) -> #DIV/0! | X5: =IF(ISBLANK(W5),"ERROR",IF(AND(W5>=23,W5<=50),"Peso Normal",IF(AND(W5<23,W5>=15),"Bajo peso",IF(W5<15,"Dato inválido",IF(W5>50,"Dato inválido"))))) -> ERROR | AD5: =IF(I5="","",TEXT(I5,"MMMM")) | AE5: =IF(I5="","",TEXT(I5,"YYYY")) | AF5: =Tabla3[[#This Row],[DIOCESIS]]&" "&"-"&" "&Tabla3[[#This Row],[PARROQUIA ECLESIAL / CENTRO CENTINELA]] -> -
A6: =A5+1 -> 5 | Q6: =IF(N6="","",((YEAR(I6)-YEAR(N6))*12+MONTH(I6)-MONTH(N6))/12) | U6: =(S6/((T6/100)*(T6/100))) -> #DIV/0! | V6: =IF(U6<18.5,"Bajo Peso ",IF(AND(U6>=18.5,U6<25),"Adecuado ",IF(AND(U6>=25,U6<30),"Sobrepeso ",IF(U6>=30,"Obesidad","Obesidad")))) -> #DIV/0! | X6: =IF(ISBLANK(W6),"ERROR",IF(AND(W6>=23,W6<=50),"Peso Normal",IF(AND(W6<23,W6>=15),"Bajo peso",IF(W6<15,"Dato inválido",IF(W6>50,"Dato inválido"))))) -> ERROR | AD6: =IF(I6="","",TEXT(I6,"MMMM")) | AE6: =IF(I6="","",TEXT(I6,"YYYY")) | AF6: =Tabla3[[#This Row],[DIOCESIS]]&" "&"-"&" "&Tabla3[[#This Row],[PARROQUIA ECLESIAL / CENTRO CENTINELA]] -> -
A7: =A6+1 -> 6 | Q7: =IF(N7="","",((YEAR(I7)-YEAR(N7))*12+MONTH(I7)-MONTH(N7))/12) | U7: =(S7/((T7/100)*(T7/100))) -> #DIV/0! | V7: =IF(U7<18.5,"Bajo Peso ",IF(AND(U7>=18.5,U7<25),"Adecuado ",IF(AND(U7>=25,U7<30),"Sobrepeso ",IF(U7>=30,"Obesidad","Obesidad")))) -> #DIV/0! | X7: =IF(ISBLANK(W7),"ERROR",IF(AND(W7>=23,W7<=50),"Peso Normal",IF(AND(W7<23,W7>=15),"Bajo peso",IF(W7<15,"Dato inválido",IF(W7>50,"Dato inválido"))))) -> ERROR | AD7: =IF(I7="","",TEXT(I7,"MMMM")) | AE7: =IF(I7="","",TEXT(I7,"YYYY")) | AF7: =Tabla3[[#This Row],[DIOCESIS]]&" "&"-"&" "&Tabla3[[#This Row],[PARROQUIA ECLESIAL / CENTRO CENTINELA]] -> -
A8: =A7+1 -> 7 | Q8: =IF(N8="","",((YEAR(I8)-YEAR(N8))*12+MONTH(I8)-MONTH(N8))/12) | U8: =(S8/((T8/100)*(T8/100))) -> #DIV/0! | V8: =IF(U8<18.5,"Bajo Peso ",IF(AND(U8>=18.5,U8<25),"Adecuado ",IF(AND(U8>=25,U8<30),"Sobrepeso ",IF(U8>=30,"Obesidad","Obesidad")))) -> #DIV/0! | X8: =IF(ISBLANK(W8),"ERROR",IF(AND(W8>=23,W8<=50),"Peso Normal",IF(AND(W8<23,W8>=15),"Bajo peso",IF(W8<15,"Dato inválido",IF(W8>50,"Dato inválido"))))) -> ERROR | AD8: =IF(I8="","",TEXT(I8,"MMMM")) | AE8: =IF(I8="","",TEXT(I8,"YYYY")) | AF8: =Tabla3[[#This Row],[DIOCESIS]]&" "&"-"&" "&Tabla3[[#This Row],[PARROQUIA ECLESIAL / CENTRO CENTINELA]] -> -
